[2024-12-02T01:25:36.611+0000] {local_task_job_runner.py:123} INFO - ::group::Pre task execution logs
[2024-12-02T01:25:36.616+0000] {taskinstance.py:2613} INFO - Dependencies all met for dep_context=non-requeueable deps ti=<TaskInstance: 01_unschedulled.fetch_events manual__2024-12-02T01:25:34.522151+00:00 [queued]>
[2024-12-02T01:25:36.619+0000] {taskinstance.py:2613} INFO - Dependencies all met for dep_context=requeueable deps ti=<TaskInstance: 01_unschedulled.fetch_events manual__2024-12-02T01:25:34.522151+00:00 [queued]>
[2024-12-02T01:25:36.619+0000] {taskinstance.py:2866} INFO - Starting attempt 1 of 1
[2024-12-02T01:25:36.623+0000] {taskinstance.py:2889} INFO - Executing <Task(BashOperator): fetch_events> on 2024-12-02 01:25:34.522151+00:00
[2024-12-02T01:25:36.626+0000] {warnings.py:112} WARNING - /home/***/.local/lib/python3.12/site-packages/***/task/task_runner/standard_task_runner.py:70: DeprecationWarning: This process (pid=976) is multi-threaded, use of fork() may lead to deadlocks in the child.
  pid = os.fork()

[2024-12-02T01:25:36.627+0000] {standard_task_runner.py:72} INFO - Started process 977 to run task
[2024-12-02T01:25:36.627+0000] {standard_task_runner.py:104} INFO - Running: ['***', 'tasks', 'run', '01_unschedulled', 'fetch_events', 'manual__2024-12-02T01:25:34.522151+00:00', '--job-id', '25', '--raw', '--subdir', 'DAGS_FOLDER/website_events.py', '--cfg-path', '/tmp/tmpvpt1p7z8']
[2024-12-02T01:25:36.628+0000] {standard_task_runner.py:105} INFO - Job 25: Subtask fetch_events
[2024-12-02T01:25:36.645+0000] {task_command.py:467} INFO - Running <TaskInstance: 01_unschedulled.fetch_events manual__2024-12-02T01:25:34.522151+00:00 [running]> on host a6ae2a39fbd5
[2024-12-02T01:25:36.781+0000] {taskinstance.py:3132} INFO - Exporting env vars: AIRFLOW_CTX_DAG_OWNER='***' AIRFLOW_CTX_DAG_ID='01_unschedulled' AIRFLOW_CTX_TASK_ID='fetch_events' AIRFLOW_CTX_EXECUTION_DATE='2024-12-02T01:25:34.522151+00:00' AIRFLOW_CTX_TRY_NUMBER='1' AIRFLOW_CTX_DAG_RUN_ID='manual__2024-12-02T01:25:34.522151+00:00'
[2024-12-02T01:25:36.782+0000] {logging_mixin.py:190} INFO - Task instance is in running state
[2024-12-02T01:25:36.782+0000] {logging_mixin.py:190} INFO -  Previous state of the Task instance: queued
[2024-12-02T01:25:36.782+0000] {logging_mixin.py:190} INFO - Current task name:fetch_events state:running start_date:2024-12-02 01:25:36.617166+00:00
[2024-12-02T01:25:36.782+0000] {logging_mixin.py:190} INFO - Dag name:01_unschedulled and current dag run status:running
[2024-12-02T01:25:36.782+0000] {taskinstance.py:731} INFO - ::endgroup::
[2024-12-02T01:25:36.783+0000] {subprocess.py:78} INFO - Tmp dir root location: /tmp
[2024-12-02T01:25:36.783+0000] {subprocess.py:88} INFO - Running command: ['/usr/bin/bash', '-c', 'mkdir -p /data/events && curl -o /data/events.json http://events_api:5000/events']
[2024-12-02T01:25:36.787+0000] {subprocess.py:99} INFO - Output:
[2024-12-02T01:25:36.789+0000] {subprocess.py:106} INFO - mkdir: cannot create directory ‘/data’: Permission denied
[2024-12-02T01:25:36.789+0000] {subprocess.py:110} INFO - Command exited with return code 1
[2024-12-02T01:25:36.793+0000] {taskinstance.py:3311} ERROR - Task failed with exception
Traceback (most recent call last):
  File "/home/airflow/.local/lib/python3.12/site-packages/airflow/models/taskinstance.py", line 767, in _execute_task
    result = _execute_callable(context=context, **execute_callable_kwargs)
             ^^^^^^^^^^^^^^^^^^^^^^^^^^^^^^^^^^^^^^^^^^^^^^^^^^^^^^^^^^^^^
  File "/home/airflow/.local/lib/python3.12/site-packages/airflow/models/taskinstance.py", line 733, in _execute_callable
    return ExecutionCallableRunner(
           ^^^^^^^^^^^^^^^^^^^^^^^^
  File "/home/airflow/.local/lib/python3.12/site-packages/airflow/utils/operator_helpers.py", line 252, in run
    return self.func(*args, **kwargs)
           ^^^^^^^^^^^^^^^^^^^^^^^^^^
  File "/home/airflow/.local/lib/python3.12/site-packages/airflow/models/baseoperator.py", line 417, in wrapper
    return func(self, *args, **kwargs)
           ^^^^^^^^^^^^^^^^^^^^^^^^^^^
  File "/home/airflow/.local/lib/python3.12/site-packages/airflow/operators/bash.py", line 276, in execute
    raise AirflowException(
airflow.exceptions.AirflowException: Bash command failed. The command returned a non-zero exit code 1.
[2024-12-02T01:25:36.795+0000] {logging_mixin.py:190} INFO - Task instance in failure state
[2024-12-02T01:25:36.795+0000] {logging_mixin.py:190} INFO - Task start:2024-12-02 01:25:36.617166+00:00 end:2024-12-02 01:25:36.795319+00:00 duration:0.178153
[2024-12-02T01:25:36.795+0000] {logging_mixin.py:190} INFO - Task:<Task(BashOperator): fetch_events> dag:<DAG: 01_unschedulled> dagrun:<DagRun 01_unschedulled @ 2024-12-02 01:25:34.522151+00:00: manual__2024-12-02T01:25:34.522151+00:00, state:running, queued_at: 2024-12-02 01:25:34.528319+00:00. externally triggered: True>
[2024-12-02T01:25:36.795+0000] {logging_mixin.py:190} INFO - Failure caused by Bash command failed. The command returned a non-zero exit code 1.
[2024-12-02T01:25:36.795+0000] {taskinstance.py:1225} INFO - Marking task as FAILED. dag_id=01_unschedulled, task_id=fetch_events, run_id=manual__2024-12-02T01:25:34.522151+00:00, execution_date=20241202T012534, start_date=20241202T012536, end_date=20241202T012536
[2024-12-02T01:25:36.800+0000] {taskinstance.py:340} INFO - ::group::Post task execution logs
[2024-12-02T01:25:36.801+0000] {standard_task_runner.py:124} ERROR - Failed to execute job 25 for task fetch_events (Bash command failed. The command returned a non-zero exit code 1.; 977)
Traceback (most recent call last):
  File "/home/airflow/.local/lib/python3.12/site-packages/airflow/task/task_runner/standard_task_runner.py", line 117, in _start_by_fork
    ret = args.func(args, dag=self.dag)
          ^^^^^^^^^^^^^^^^^^^^^^^^^^^^^
  File "/home/airflow/.local/lib/python3.12/site-packages/airflow/cli/cli_config.py", line 49, in command
    return func(*args, **kwargs)
           ^^^^^^^^^^^^^^^^^^^^^
  File "/home/airflow/.local/lib/python3.12/site-packages/airflow/utils/cli.py", line 116, in wrapper
    return f(*args, **kwargs)
           ^^^^^^^^^^^^^^^^^^
  File "/home/airflow/.local/lib/python3.12/site-packages/airflow/cli/commands/task_command.py", line 483, in task_run
    task_return_code = _run_task_by_selected_method(args, _dag, ti)
                       ^^^^^^^^^^^^^^^^^^^^^^^^^^^^^^^^^^^^^^^^^^^^
  File "/home/airflow/.local/lib/python3.12/site-packages/airflow/cli/commands/task_command.py", line 256, in _run_task_by_selected_method
    return _run_raw_task(args, ti)
           ^^^^^^^^^^^^^^^^^^^^^^^
  File "/home/airflow/.local/lib/python3.12/site-packages/airflow/cli/commands/task_command.py", line 341, in _run_raw_task
    return ti._run_raw_task(
           ^^^^^^^^^^^^^^^^^
  File "/home/airflow/.local/lib/python3.12/site-packages/airflow/utils/session.py", line 97, in wrapper
    return func(*args, session=session, **kwargs)
           ^^^^^^^^^^^^^^^^^^^^^^^^^^^^^^^^^^^^^^
  File "/home/airflow/.local/lib/python3.12/site-packages/airflow/models/taskinstance.py", line 3005, in _run_raw_task
    return _run_raw_task(
           ^^^^^^^^^^^^^^
  File "/home/airflow/.local/lib/python3.12/site-packages/airflow/models/taskinstance.py", line 273, in _run_raw_task
    TaskInstance._execute_task_with_callbacks(
  File "/home/airflow/.local/lib/python3.12/site-packages/airflow/models/taskinstance.py", line 3159, in _execute_task_with_callbacks
    result = self._execute_task(context, task_orig)
             ^^^^^^^^^^^^^^^^^^^^^^^^^^^^^^^^^^^^^^
  File "/home/airflow/.local/lib/python3.12/site-packages/airflow/models/taskinstance.py", line 3183, in _execute_task
    return _execute_task(self, context, task_orig)
           ^^^^^^^^^^^^^^^^^^^^^^^^^^^^^^^^^^^^^^^
  File "/home/airflow/.local/lib/python3.12/site-packages/airflow/models/taskinstance.py", line 767, in _execute_task
    result = _execute_callable(context=context, **execute_callable_kwargs)
             ^^^^^^^^^^^^^^^^^^^^^^^^^^^^^^^^^^^^^^^^^^^^^^^^^^^^^^^^^^^^^
  File "/home/airflow/.local/lib/python3.12/site-packages/airflow/models/taskinstance.py", line 733, in _execute_callable
    return ExecutionCallableRunner(
           ^^^^^^^^^^^^^^^^^^^^^^^^
  File "/home/airflow/.local/lib/python3.12/site-packages/airflow/utils/operator_helpers.py", line 252, in run
    return self.func(*args, **kwargs)
           ^^^^^^^^^^^^^^^^^^^^^^^^^^
  File "/home/airflow/.local/lib/python3.12/site-packages/airflow/models/baseoperator.py", line 417, in wrapper
    return func(self, *args, **kwargs)
           ^^^^^^^^^^^^^^^^^^^^^^^^^^^
  File "/home/airflow/.local/lib/python3.12/site-packages/airflow/operators/bash.py", line 276, in execute
    raise AirflowException(
airflow.exceptions.AirflowException: Bash command failed. The command returned a non-zero exit code 1.
[2024-12-02T01:25:36.809+0000] {local_task_job_runner.py:266} INFO - Task exited with return code 1
[2024-12-02T01:25:36.893+0000] {taskinstance.py:3895} INFO - 0 downstream tasks scheduled from follow-on schedule check
[2024-12-02T01:25:36.895+0000] {local_task_job_runner.py:245} INFO - ::endgroup::
