[2024-12-19T22:07:31.661+0000] {local_task_job_runner.py:123} INFO - ::group::Pre task execution logs
[2024-12-19T22:07:31.666+0000] {taskinstance.py:2613} INFO - Dependencies all met for dep_context=non-requeueable deps ti=<TaskInstance: atomic_idm.calculate_Stats manual__2024-12-19T22:07:29.723539+00:00 [queued]>
[2024-12-19T22:07:31.669+0000] {taskinstance.py:2613} INFO - Dependencies all met for dep_context=requeueable deps ti=<TaskInstance: atomic_idm.calculate_Stats manual__2024-12-19T22:07:29.723539+00:00 [queued]>
[2024-12-19T22:07:31.669+0000] {taskinstance.py:2866} INFO - Starting attempt 1 of 1
[2024-12-19T22:07:31.739+0000] {taskinstance.py:2889} INFO - Executing <Task(PythonOperator): calculate_Stats> on 2024-12-19 22:07:29.723539+00:00
[2024-12-19T22:07:31.742+0000] {warnings.py:112} WARNING - /home/***/.local/lib/python3.12/site-packages/***/task/task_runner/standard_task_runner.py:70: DeprecationWarning: This process (pid=894) is multi-threaded, use of fork() may lead to deadlocks in the child.
  pid = os.fork()

[2024-12-19T22:07:31.743+0000] {standard_task_runner.py:72} INFO - Started process 895 to run task
[2024-12-19T22:07:31.743+0000] {standard_task_runner.py:104} INFO - Running: ['***', 'tasks', 'run', 'atomic_idm', 'calculate_Stats', 'manual__2024-12-19T22:07:29.723539+00:00', '--job-id', '258', '--raw', '--subdir', 'DAGS_FOLDER/atomicity_idempotency.py', '--cfg-path', '/tmp/tmp33mwb_1c']
[2024-12-19T22:07:31.744+0000] {standard_task_runner.py:105} INFO - Job 258: Subtask calculate_Stats
[2024-12-19T22:07:31.760+0000] {task_command.py:467} INFO - Running <TaskInstance: atomic_idm.calculate_Stats manual__2024-12-19T22:07:29.723539+00:00 [running]> on host 447a91cba43e
[2024-12-19T22:07:31.784+0000] {taskinstance.py:3132} INFO - Exporting env vars: AIRFLOW_CTX_DAG_OWNER='***' AIRFLOW_CTX_DAG_ID='atomic_idm' AIRFLOW_CTX_TASK_ID='calculate_Stats' AIRFLOW_CTX_EXECUTION_DATE='2024-12-19T22:07:29.723539+00:00' AIRFLOW_CTX_TRY_NUMBER='1' AIRFLOW_CTX_DAG_RUN_ID='manual__2024-12-19T22:07:29.723539+00:00'
[2024-12-19T22:07:31.784+0000] {logging_mixin.py:190} INFO - Task instance is in running state
[2024-12-19T22:07:31.784+0000] {logging_mixin.py:190} INFO -  Previous state of the Task instance: queued
[2024-12-19T22:07:31.784+0000] {logging_mixin.py:190} INFO - Current task name:calculate_Stats state:running start_date:2024-12-19 22:07:31.666877+00:00
[2024-12-19T22:07:31.785+0000] {logging_mixin.py:190} INFO - Dag name:atomic_idm and current dag run status:running
[2024-12-19T22:07:31.785+0000] {taskinstance.py:731} INFO - ::endgroup::
[2024-12-19T22:07:31.788+0000] {taskinstance.py:3311} ERROR - Task failed with exception
Traceback (most recent call last):
  File "/home/airflow/.local/lib/python3.12/site-packages/airflow/models/taskinstance.py", line 767, in _execute_task
    result = _execute_callable(context=context, **execute_callable_kwargs)
             ^^^^^^^^^^^^^^^^^^^^^^^^^^^^^^^^^^^^^^^^^^^^^^^^^^^^^^^^^^^^^
  File "/home/airflow/.local/lib/python3.12/site-packages/airflow/models/taskinstance.py", line 733, in _execute_callable
    return ExecutionCallableRunner(
           ^^^^^^^^^^^^^^^^^^^^^^^^
  File "/home/airflow/.local/lib/python3.12/site-packages/airflow/utils/operator_helpers.py", line 252, in run
    return self.func(*args, **kwargs)
           ^^^^^^^^^^^^^^^^^^^^^^^^^^
  File "/home/airflow/.local/lib/python3.12/site-packages/airflow/models/baseoperator.py", line 417, in wrapper
    return func(self, *args, **kwargs)
           ^^^^^^^^^^^^^^^^^^^^^^^^^^^
  File "/home/airflow/.local/lib/python3.12/site-packages/airflow/operators/python.py", line 238, in execute
    return_value = self.execute_callable()
                   ^^^^^^^^^^^^^^^^^^^^^^^
  File "/home/airflow/.local/lib/python3.12/site-packages/airflow/operators/python.py", line 256, in execute_callable
    return runner.run(*self.op_args, **self.op_kwargs)
           ^^^^^^^^^^^^^^^^^^^^^^^^^^^^^^^^^^^^^^^^^^^
  File "/home/airflow/.local/lib/python3.12/site-packages/airflow/utils/operator_helpers.py", line 252, in run
    return self.func(*args, **kwargs)
           ^^^^^^^^^^^^^^^^^^^^^^^^^^
  File "/opt/airflow/dags/atomicity_idempotency.py", line 53, in __calculate_stats
    stats = events.groupby(["date", "user"]).size().reset_index()
            ^^^^^^^^^^^^^^^^^^^^^^^^^^^^^^^^
  File "/home/airflow/.local/lib/python3.12/site-packages/pandas/core/frame.py", line 8869, in groupby
    return DataFrameGroupBy(
           ^^^^^^^^^^^^^^^^^
  File "/home/airflow/.local/lib/python3.12/site-packages/pandas/core/groupby/groupby.py", line 1278, in __init__
    grouper, exclusions, obj = get_grouper(
                               ^^^^^^^^^^^^
  File "/home/airflow/.local/lib/python3.12/site-packages/pandas/core/groupby/grouper.py", line 1009, in get_grouper
    raise KeyError(gpr)
KeyError: 'date'
[2024-12-19T22:07:31.792+0000] {logging_mixin.py:190} INFO - Task instance in failure state
[2024-12-19T22:07:31.792+0000] {logging_mixin.py:190} INFO - Task start:2024-12-19 22:07:31.666877+00:00 end:2024-12-19 22:07:31.792708+00:00 duration:0.125831
[2024-12-19T22:07:31.793+0000] {logging_mixin.py:190} INFO - Task:<Task(PythonOperator): calculate_Stats> dag:<DAG: atomic_idm> dagrun:<DagRun atomic_idm @ 2024-12-19 22:07:29.723539+00:00: manual__2024-12-19T22:07:29.723539+00:00, state:running, queued_at: 2024-12-19 22:07:29.735010+00:00. externally triggered: True>
[2024-12-19T22:07:31.793+0000] {logging_mixin.py:190} INFO - Failure caused by 'date'
[2024-12-19T22:07:31.793+0000] {taskinstance.py:1225} INFO - Marking task as FAILED. dag_id=atomic_idm, task_id=calculate_Stats, run_id=manual__2024-12-19T22:07:29.723539+00:00, execution_date=20241219T220729, start_date=20241219T220731, end_date=20241219T220731
[2024-12-19T22:07:31.796+0000] {taskinstance.py:340} INFO - ::group::Post task execution logs
[2024-12-19T22:07:31.796+0000] {standard_task_runner.py:124} ERROR - Failed to execute job 258 for task calculate_Stats ('date'; 895)
Traceback (most recent call last):
  File "/home/airflow/.local/lib/python3.12/site-packages/airflow/task/task_runner/standard_task_runner.py", line 117, in _start_by_fork
    ret = args.func(args, dag=self.dag)
          ^^^^^^^^^^^^^^^^^^^^^^^^^^^^^
  File "/home/airflow/.local/lib/python3.12/site-packages/airflow/cli/cli_config.py", line 49, in command
    return func(*args, **kwargs)
           ^^^^^^^^^^^^^^^^^^^^^
  File "/home/airflow/.local/lib/python3.12/site-packages/airflow/utils/cli.py", line 116, in wrapper
    return f(*args, **kwargs)
           ^^^^^^^^^^^^^^^^^^
  File "/home/airflow/.local/lib/python3.12/site-packages/airflow/cli/commands/task_command.py", line 483, in task_run
    task_return_code = _run_task_by_selected_method(args, _dag, ti)
                       ^^^^^^^^^^^^^^^^^^^^^^^^^^^^^^^^^^^^^^^^^^^^
  File "/home/airflow/.local/lib/python3.12/site-packages/airflow/cli/commands/task_command.py", line 256, in _run_task_by_selected_method
    return _run_raw_task(args, ti)
           ^^^^^^^^^^^^^^^^^^^^^^^
  File "/home/airflow/.local/lib/python3.12/site-packages/airflow/cli/commands/task_command.py", line 341, in _run_raw_task
    return ti._run_raw_task(
           ^^^^^^^^^^^^^^^^^
  File "/home/airflow/.local/lib/python3.12/site-packages/airflow/utils/session.py", line 97, in wrapper
    return func(*args, session=session, **kwargs)
           ^^^^^^^^^^^^^^^^^^^^^^^^^^^^^^^^^^^^^^
  File "/home/airflow/.local/lib/python3.12/site-packages/airflow/models/taskinstance.py", line 3005, in _run_raw_task
    return _run_raw_task(
           ^^^^^^^^^^^^^^
  File "/home/airflow/.local/lib/python3.12/site-packages/airflow/models/taskinstance.py", line 273, in _run_raw_task
    TaskInstance._execute_task_with_callbacks(
  File "/home/airflow/.local/lib/python3.12/site-packages/airflow/models/taskinstance.py", line 3159, in _execute_task_with_callbacks
    result = self._execute_task(context, task_orig)
             ^^^^^^^^^^^^^^^^^^^^^^^^^^^^^^^^^^^^^^
  File "/home/airflow/.local/lib/python3.12/site-packages/airflow/models/taskinstance.py", line 3183, in _execute_task
    return _execute_task(self, context, task_orig)
           ^^^^^^^^^^^^^^^^^^^^^^^^^^^^^^^^^^^^^^^
  File "/home/airflow/.local/lib/python3.12/site-packages/airflow/models/taskinstance.py", line 767, in _execute_task
    result = _execute_callable(context=context, **execute_callable_kwargs)
             ^^^^^^^^^^^^^^^^^^^^^^^^^^^^^^^^^^^^^^^^^^^^^^^^^^^^^^^^^^^^^
  File "/home/airflow/.local/lib/python3.12/site-packages/airflow/models/taskinstance.py", line 733, in _execute_callable
    return ExecutionCallableRunner(
           ^^^^^^^^^^^^^^^^^^^^^^^^
  File "/home/airflow/.local/lib/python3.12/site-packages/airflow/utils/operator_helpers.py", line 252, in run
    return self.func(*args, **kwargs)
           ^^^^^^^^^^^^^^^^^^^^^^^^^^
  File "/home/airflow/.local/lib/python3.12/site-packages/airflow/models/baseoperator.py", line 417, in wrapper
    return func(self, *args, **kwargs)
           ^^^^^^^^^^^^^^^^^^^^^^^^^^^
  File "/home/airflow/.local/lib/python3.12/site-packages/airflow/operators/python.py", line 238, in execute
    return_value = self.execute_callable()
                   ^^^^^^^^^^^^^^^^^^^^^^^
  File "/home/airflow/.local/lib/python3.12/site-packages/airflow/operators/python.py", line 256, in execute_callable
    return runner.run(*self.op_args, **self.op_kwargs)
           ^^^^^^^^^^^^^^^^^^^^^^^^^^^^^^^^^^^^^^^^^^^
  File "/home/airflow/.local/lib/python3.12/site-packages/airflow/utils/operator_helpers.py", line 252, in run
    return self.func(*args, **kwargs)
           ^^^^^^^^^^^^^^^^^^^^^^^^^^
  File "/opt/airflow/dags/atomicity_idempotency.py", line 53, in __calculate_stats
    stats = events.groupby(["date", "user"]).size().reset_index()
            ^^^^^^^^^^^^^^^^^^^^^^^^^^^^^^^^
  File "/home/airflow/.local/lib/python3.12/site-packages/pandas/core/frame.py", line 8869, in groupby
    return DataFrameGroupBy(
           ^^^^^^^^^^^^^^^^^
  File "/home/airflow/.local/lib/python3.12/site-packages/pandas/core/groupby/groupby.py", line 1278, in __init__
    grouper, exclusions, obj = get_grouper(
                               ^^^^^^^^^^^^
  File "/home/airflow/.local/lib/python3.12/site-packages/pandas/core/groupby/grouper.py", line 1009, in get_grouper
    raise KeyError(gpr)
KeyError: 'date'
[2024-12-19T22:07:31.804+0000] {local_task_job_runner.py:266} INFO - Task exited with return code 1
[2024-12-19T22:07:31.809+0000] {taskinstance.py:3895} INFO - 0 downstream tasks scheduled from follow-on schedule check
[2024-12-19T22:07:31.810+0000] {local_task_job_runner.py:245} INFO - ::endgroup::
