[2024-12-19T21:55:38.920+0000] {local_task_job_runner.py:123} INFO - ::group::Pre task execution logs
[2024-12-19T21:55:38.949+0000] {taskinstance.py:2613} INFO - Dependencies all met for dep_context=non-requeueable deps ti=<TaskInstance: atomic_idm.calculate_Stats scheduled__2024-12-10T00:00:00+00:00 [queued]>
[2024-12-19T21:55:38.967+0000] {taskinstance.py:2613} INFO - Dependencies all met for dep_context=requeueable deps ti=<TaskInstance: atomic_idm.calculate_Stats scheduled__2024-12-10T00:00:00+00:00 [queued]>
[2024-12-19T21:55:38.970+0000] {taskinstance.py:2866} INFO - Starting attempt 1 of 1
[2024-12-19T21:55:39.249+0000] {taskinstance.py:2889} INFO - Executing <Task(PythonOperator): calculate_Stats> on 2024-12-10 00:00:00+00:00
[2024-12-19T21:55:39.258+0000] {warnings.py:112} WARNING - /home/***/.local/lib/python3.12/site-packages/***/task/task_runner/standard_task_runner.py:70: DeprecationWarning: This process (pid=604) is multi-threaded, use of fork() may lead to deadlocks in the child.
  pid = os.fork()

[2024-12-19T21:55:39.264+0000] {standard_task_runner.py:72} INFO - Started process 645 to run task
[2024-12-19T21:55:39.260+0000] {standard_task_runner.py:104} INFO - Running: ['***', 'tasks', 'run', 'atomic_idm', 'calculate_Stats', 'scheduled__2024-12-10T00:00:00+00:00', '--job-id', '232', '--raw', '--subdir', 'DAGS_FOLDER/atomicity_idempotency.py', '--cfg-path', '/tmp/tmp03_1xdzo']
[2024-12-19T21:55:39.266+0000] {standard_task_runner.py:105} INFO - Job 232: Subtask calculate_Stats
[2024-12-19T21:55:39.369+0000] {task_command.py:467} INFO - Running <TaskInstance: atomic_idm.calculate_Stats scheduled__2024-12-10T00:00:00+00:00 [running]> on host 447a91cba43e
[2024-12-19T21:55:39.547+0000] {taskinstance.py:3132} INFO - Exporting env vars: AIRFLOW_CTX_DAG_OWNER='***' AIRFLOW_CTX_DAG_ID='atomic_idm' AIRFLOW_CTX_TASK_ID='calculate_Stats' AIRFLOW_CTX_EXECUTION_DATE='2024-12-10T00:00:00+00:00' AIRFLOW_CTX_TRY_NUMBER='1' AIRFLOW_CTX_DAG_RUN_ID='scheduled__2024-12-10T00:00:00+00:00'
[2024-12-19T21:55:39.550+0000] {logging_mixin.py:190} INFO - Task instance is in running state
[2024-12-19T21:55:39.553+0000] {logging_mixin.py:190} INFO -  Previous state of the Task instance: queued
[2024-12-19T21:55:39.554+0000] {logging_mixin.py:190} INFO - Current task name:calculate_Stats state:running start_date:2024-12-19 21:55:38.953368+00:00
[2024-12-19T21:55:39.554+0000] {logging_mixin.py:190} INFO - Dag name:atomic_idm and current dag run status:running
[2024-12-19T21:55:39.554+0000] {taskinstance.py:731} INFO - ::endgroup::
[2024-12-19T21:55:39.557+0000] {taskinstance.py:3311} ERROR - Task failed with exception
Traceback (most recent call last):
  File "/home/airflow/.local/lib/python3.12/site-packages/airflow/models/taskinstance.py", line 767, in _execute_task
    result = _execute_callable(context=context, **execute_callable_kwargs)
             ^^^^^^^^^^^^^^^^^^^^^^^^^^^^^^^^^^^^^^^^^^^^^^^^^^^^^^^^^^^^^
  File "/home/airflow/.local/lib/python3.12/site-packages/airflow/models/taskinstance.py", line 733, in _execute_callable
    return ExecutionCallableRunner(
           ^^^^^^^^^^^^^^^^^^^^^^^^
  File "/home/airflow/.local/lib/python3.12/site-packages/airflow/utils/operator_helpers.py", line 252, in run
    return self.func(*args, **kwargs)
           ^^^^^^^^^^^^^^^^^^^^^^^^^^
  File "/home/airflow/.local/lib/python3.12/site-packages/airflow/models/baseoperator.py", line 417, in wrapper
    return func(self, *args, **kwargs)
           ^^^^^^^^^^^^^^^^^^^^^^^^^^^
  File "/home/airflow/.local/lib/python3.12/site-packages/airflow/operators/python.py", line 238, in execute
    return_value = self.execute_callable()
                   ^^^^^^^^^^^^^^^^^^^^^^^
  File "/home/airflow/.local/lib/python3.12/site-packages/airflow/operators/python.py", line 256, in execute_callable
    return runner.run(*self.op_args, **self.op_kwargs)
           ^^^^^^^^^^^^^^^^^^^^^^^^^^^^^^^^^^^^^^^^^^^
  File "/home/airflow/.local/lib/python3.12/site-packages/airflow/utils/operator_helpers.py", line 252, in run
    return self.func(*args, **kwargs)
           ^^^^^^^^^^^^^^^^^^^^^^^^^^
  File "/opt/airflow/dags/atomicity_idempotency.py", line 39, in __calculate_stats
    events = pd.read_json(input_path)
             ^^^^^^^^^^^^^^^^^^^^^^^^
  File "/home/airflow/.local/lib/python3.12/site-packages/pandas/io/json/_json.py", line 780, in read_json
    json_reader = JsonReader(
                  ^^^^^^^^^^^
  File "/home/airflow/.local/lib/python3.12/site-packages/pandas/io/json/_json.py", line 893, in __init__
    data = self._get_data_from_filepath(filepath_or_buffer)
           ^^^^^^^^^^^^^^^^^^^^^^^^^^^^^^^^^^^^^^^^^^^^^^^^
  File "/home/airflow/.local/lib/python3.12/site-packages/pandas/io/json/_json.py", line 949, in _get_data_from_filepath
    raise FileNotFoundError(f"File {filepath_or_buffer} does not exist")
FileNotFoundError: File /tmp/data/events_2024-12-10.json does not exist
[2024-12-19T21:55:39.578+0000] {logging_mixin.py:190} INFO - Task instance in failure state
[2024-12-19T21:55:39.578+0000] {logging_mixin.py:190} INFO - Task start:2024-12-19 21:55:38.953368+00:00 end:2024-12-19 21:55:39.578029+00:00 duration:0.624661
[2024-12-19T21:55:39.578+0000] {logging_mixin.py:190} INFO - Task:<Task(PythonOperator): calculate_Stats> dag:<DAG: atomic_idm> dagrun:<DagRun atomic_idm @ 2024-12-10 00:00:00+00:00: scheduled__2024-12-10T00:00:00+00:00, state:running, queued_at: 2024-12-19 21:55:34.740740+00:00. externally triggered: False>
[2024-12-19T21:55:39.579+0000] {logging_mixin.py:190} INFO - Failure caused by File /tmp/data/events_2024-12-10.json does not exist
[2024-12-19T21:55:39.579+0000] {taskinstance.py:1225} INFO - Marking task as FAILED. dag_id=atomic_idm, task_id=calculate_Stats, run_id=scheduled__2024-12-10T00:00:00+00:00, execution_date=20241210T000000, start_date=20241219T215538, end_date=20241219T215539
[2024-12-19T21:55:39.596+0000] {taskinstance.py:340} INFO - ::group::Post task execution logs
[2024-12-19T21:55:39.599+0000] {standard_task_runner.py:124} ERROR - Failed to execute job 232 for task calculate_Stats (File /tmp/data/events_2024-12-10.json does not exist; 645)
Traceback (most recent call last):
  File "/home/airflow/.local/lib/python3.12/site-packages/airflow/task/task_runner/standard_task_runner.py", line 117, in _start_by_fork
    ret = args.func(args, dag=self.dag)
          ^^^^^^^^^^^^^^^^^^^^^^^^^^^^^
  File "/home/airflow/.local/lib/python3.12/site-packages/airflow/cli/cli_config.py", line 49, in command
    return func(*args, **kwargs)
           ^^^^^^^^^^^^^^^^^^^^^
  File "/home/airflow/.local/lib/python3.12/site-packages/airflow/utils/cli.py", line 116, in wrapper
    return f(*args, **kwargs)
           ^^^^^^^^^^^^^^^^^^
  File "/home/airflow/.local/lib/python3.12/site-packages/airflow/cli/commands/task_command.py", line 483, in task_run
    task_return_code = _run_task_by_selected_method(args, _dag, ti)
                       ^^^^^^^^^^^^^^^^^^^^^^^^^^^^^^^^^^^^^^^^^^^^
  File "/home/airflow/.local/lib/python3.12/site-packages/airflow/cli/commands/task_command.py", line 256, in _run_task_by_selected_method
    return _run_raw_task(args, ti)
           ^^^^^^^^^^^^^^^^^^^^^^^
  File "/home/airflow/.local/lib/python3.12/site-packages/airflow/cli/commands/task_command.py", line 341, in _run_raw_task
    return ti._run_raw_task(
           ^^^^^^^^^^^^^^^^^
  File "/home/airflow/.local/lib/python3.12/site-packages/airflow/utils/session.py", line 97, in wrapper
    return func(*args, session=session, **kwargs)
           ^^^^^^^^^^^^^^^^^^^^^^^^^^^^^^^^^^^^^^
  File "/home/airflow/.local/lib/python3.12/site-packages/airflow/models/taskinstance.py", line 3005, in _run_raw_task
    return _run_raw_task(
           ^^^^^^^^^^^^^^
  File "/home/airflow/.local/lib/python3.12/site-packages/airflow/models/taskinstance.py", line 273, in _run_raw_task
    TaskInstance._execute_task_with_callbacks(
  File "/home/airflow/.local/lib/python3.12/site-packages/airflow/models/taskinstance.py", line 3159, in _execute_task_with_callbacks
    result = self._execute_task(context, task_orig)
             ^^^^^^^^^^^^^^^^^^^^^^^^^^^^^^^^^^^^^^
  File "/home/airflow/.local/lib/python3.12/site-packages/airflow/models/taskinstance.py", line 3183, in _execute_task
    return _execute_task(self, context, task_orig)
           ^^^^^^^^^^^^^^^^^^^^^^^^^^^^^^^^^^^^^^^
  File "/home/airflow/.local/lib/python3.12/site-packages/airflow/models/taskinstance.py", line 767, in _execute_task
    result = _execute_callable(context=context, **execute_callable_kwargs)
             ^^^^^^^^^^^^^^^^^^^^^^^^^^^^^^^^^^^^^^^^^^^^^^^^^^^^^^^^^^^^^
  File "/home/airflow/.local/lib/python3.12/site-packages/airflow/models/taskinstance.py", line 733, in _execute_callable
    return ExecutionCallableRunner(
           ^^^^^^^^^^^^^^^^^^^^^^^^
  File "/home/airflow/.local/lib/python3.12/site-packages/airflow/utils/operator_helpers.py", line 252, in run
    return self.func(*args, **kwargs)
           ^^^^^^^^^^^^^^^^^^^^^^^^^^
  File "/home/airflow/.local/lib/python3.12/site-packages/airflow/models/baseoperator.py", line 417, in wrapper
    return func(self, *args, **kwargs)
           ^^^^^^^^^^^^^^^^^^^^^^^^^^^
  File "/home/airflow/.local/lib/python3.12/site-packages/airflow/operators/python.py", line 238, in execute
    return_value = self.execute_callable()
                   ^^^^^^^^^^^^^^^^^^^^^^^
  File "/home/airflow/.local/lib/python3.12/site-packages/airflow/operators/python.py", line 256, in execute_callable
    return runner.run(*self.op_args, **self.op_kwargs)
           ^^^^^^^^^^^^^^^^^^^^^^^^^^^^^^^^^^^^^^^^^^^
  File "/home/airflow/.local/lib/python3.12/site-packages/airflow/utils/operator_helpers.py", line 252, in run
    return self.func(*args, **kwargs)
           ^^^^^^^^^^^^^^^^^^^^^^^^^^
  File "/opt/airflow/dags/atomicity_idempotency.py", line 39, in __calculate_stats
    events = pd.read_json(input_path)
             ^^^^^^^^^^^^^^^^^^^^^^^^
  File "/home/airflow/.local/lib/python3.12/site-packages/pandas/io/json/_json.py", line 780, in read_json
    json_reader = JsonReader(
                  ^^^^^^^^^^^
  File "/home/airflow/.local/lib/python3.12/site-packages/pandas/io/json/_json.py", line 893, in __init__
    data = self._get_data_from_filepath(filepath_or_buffer)
           ^^^^^^^^^^^^^^^^^^^^^^^^^^^^^^^^^^^^^^^^^^^^^^^^
  File "/home/airflow/.local/lib/python3.12/site-packages/pandas/io/json/_json.py", line 949, in _get_data_from_filepath
    raise FileNotFoundError(f"File {filepath_or_buffer} does not exist")
FileNotFoundError: File /tmp/data/events_2024-12-10.json does not exist
[2024-12-19T21:55:39.616+0000] {local_task_job_runner.py:266} INFO - Task exited with return code 1
[2024-12-19T21:55:39.641+0000] {taskinstance.py:3895} INFO - 0 downstream tasks scheduled from follow-on schedule check
[2024-12-19T21:55:39.645+0000] {local_task_job_runner.py:245} INFO - ::endgroup::
